<!DOCTYPE html>
<html lang="zh-CN">
<head>
    <meta charset="UTF-8">
    <meta name="viewport" content="width=device-width, initial-scale=1.0,maximum-scale=1.0, user-scalable=no"/>
    <title>Promise错误处理</title>
</head>
<body>

<script>
    let p1 = new Promise((resolve, reject) => {
        reject("p1")
    }).then(value => {

    }, reason => {
        console.log(reason)//这里对错误有处理，就不会再抛给catch了
        return new Promise((resolve, reject) => {
            reject("内层")
        })
    }).catch(error => {//catch会捕获所有未处理的错误
        console.log(error)
    })

    class MyError extends Error{
        constructor(msg) {
            super(msg);
            this.name = "MyError"
        }
    }

    new Promise((resolve, reject) => {
        throw new MyError("这是自定义错误")//同步的可以使用throw 抛出错误  异步的只能用reject抛出错误
    }).then(value => {},reason => {
        console.log(reason)//
        console.log(reason.message)//这是自定义错误
    }).finally(()=>{
        console.log("永远会执行")
    })
</script>
</body>
</html>
